Traceback (most recent call last):
  File "/Library/Frameworks/Python.framework/Versions/3.10/lib/python3.10/site-packages/jupyter_cache/executors/utils.py", line 58, in single_nb_execution
    executenb(
  File "/Users/belka/Library/Python/3.10/lib/python/site-packages/nbclient/client.py", line 1265, in execute
    return NotebookClient(nb=nb, resources=resources, km=km, **kwargs).execute()
  File "/Users/belka/Library/Python/3.10/lib/python/site-packages/jupyter_core/utils/__init__.py", line 166, in wrapped
    return loop.run_until_complete(inner)
  File "/Library/Frameworks/Python.framework/Versions/3.10/lib/python3.10/asyncio/base_events.py", line 646, in run_until_complete
    return future.result()
  File "/Users/belka/Library/Python/3.10/lib/python/site-packages/nbclient/client.py", line 703, in async_execute
    await self.async_execute_cell(
  File "/Users/belka/Library/Python/3.10/lib/python/site-packages/nbclient/client.py", line 1021, in async_execute_cell
    await self._check_raise_for_error(cell, cell_index, exec_reply)
  File "/Users/belka/Library/Python/3.10/lib/python/site-packages/nbclient/client.py", line 915, in _check_raise_for_error
    raise CellExecutionError.from_cell_and_msg(cell, exec_reply_content)
nbclient.exceptions.CellExecutionError: An error occurred while executing the following cell:
------------------
# Создаем один общий буфер (объединение всех зон)
combined_buffer = metro_buff_500.geometry.union_all()

# Фильтруем кафе внутри общего буфера
cafes_within = cafes_utm[cafes_utm.geometry.within(combined_buffer)]
------------------

[0;31m---------------------------------------------------------------------------[0m
[0;31mAttributeError[0m                            Traceback (most recent call last)
Cell [0;32mIn[16], line 2[0m
[1;32m      1[0m [38;5;66;03m# Создаем один общий буфер (объединение всех зон)[39;00m
[0;32m----> 2[0m combined_buffer [38;5;241m=[39m [43mmetro_buff_500[49m[38;5;241;43m.[39;49m[43mgeometry[49m[38;5;241;43m.[39;49m[43munion_all[49m()
[1;32m      4[0m [38;5;66;03m# Фильтруем кафе внутри общего буфера[39;00m
[1;32m      5[0m cafes_within [38;5;241m=[39m cafes_utm[cafes_utm[38;5;241m.[39mgeometry[38;5;241m.[39mwithin(combined_buffer)]

File [0;32m/Library/Frameworks/Python.framework/Versions/3.10/lib/python3.10/site-packages/pandas/core/generic.py:6299[0m, in [0;36mNDFrame.__getattr__[0;34m(self, name)[0m
[1;32m   6292[0m [38;5;28;01mif[39;00m (
[1;32m   6293[0m     name [38;5;129;01mnot[39;00m [38;5;129;01min[39;00m [38;5;28mself[39m[38;5;241m.[39m_internal_names_set
[1;32m   6294[0m     [38;5;129;01mand[39;00m name [38;5;129;01mnot[39;00m [38;5;129;01min[39;00m [38;5;28mself[39m[38;5;241m.[39m_metadata
[1;32m   6295[0m     [38;5;129;01mand[39;00m name [38;5;129;01mnot[39;00m [38;5;129;01min[39;00m [38;5;28mself[39m[38;5;241m.[39m_accessors
[1;32m   6296[0m     [38;5;129;01mand[39;00m [38;5;28mself[39m[38;5;241m.[39m_info_axis[38;5;241m.[39m_can_hold_identifiers_and_holds_name(name)
[1;32m   6297[0m ):
[1;32m   6298[0m     [38;5;28;01mreturn[39;00m [38;5;28mself[39m[name]
[0;32m-> 6299[0m [38;5;28;01mreturn[39;00m [38;5;28;43mobject[39;49m[38;5;241;43m.[39;49m[38;5;21;43m__getattribute__[39;49m[43m([49m[38;5;28;43mself[39;49m[43m,[49m[43m [49m[43mname[49m[43m)[49m

[0;31mAttributeError[0m: 'GeoSeries' object has no attribute 'union_all'
AttributeError: 'GeoSeries' object has no attribute 'union_all'

